<?xml version="1.0" encoding="utf-8"?>
<!-- This URDF was automatically created by SolidWorks to URDF Exporter! Originally created by Stephen Brawner (brawner@gmail.com) 
     Commit Version: 1.6.0-1-g15f4949  Build Version: 1.6.7594.29634
     For more information, please see http://wiki.ros.org/sw_urdf_exporter -->
<robot
  name="shipbot">
  <gazebo>
    <plugin name="gazebo_ros_control" filename="libgazebo_ros_control.so">
      <robotNamespace>/shipbot</robotNamespace>
    </plugin>
  </gazebo>
  <link name="world"/>
  <joint 
    name="world_to_link0"
    type="fixed">
    <origin xyz="0 0 0.0889" rpy="0 0 0"/>
    <parent link="world"/>
    <child link="link0"/>
  </joint>
  <link
    name="link0">
    <inertial>
      <origin
        xyz="0.0022949 -0.015486 -0.0003338"
        rpy="0 0 0" />
      <mass
        value="0.1595" />
      <inertia
        ixx="8.441E-05"
        ixy="4.575E-06"
        ixz="-7.3706E-08"
        iyy="5.6573E-05"
        iyz="5.1405E-08"
        izz="0.0001337" />
    </inertial>
    <visual>
      <origin
        xyz="0 0 0"
        rpy="0 0 0" />
      <geometry>
        <mesh
          filename="package://shipbot_urdf/meshes/link0.STL" />
      </geometry>
      <material
        name="">
        <color
          rgba="0.79216 0.81961 0.93333 1" />
      </material>
    </visual>
    <collision>
      <origin
        xyz="0 0 0"
        rpy="0 0 0" />
      <geometry>
        <mesh
          filename="package://shipbot_urdf/meshes/link0.STL" />
      </geometry>
    </collision>
  </link>
  <link
    name="link1">
    <inertial>
      <origin
        xyz="-0.043048 -0.0089791 0.064419"
        rpy="0 0 0" />
      <mass
        value="0.23698" />
      <inertia
        ixx="0.00018609"
        ixy="3.2809E-07"
        ixz="4.3594E-07"
        iyy="8.7525E-05"
        iyz="9.4885E-06"
        izz="0.00011907" />
    </inertial>
    <visual>
      <origin
        xyz="0 0 0"
        rpy="0 0 0" />
      <geometry>
        <mesh
          filename="package://shipbot_urdf/meshes/link1.STL" />
      </geometry>
      <material
        name="">
        <color
          rgba="0.79216 0.81961 0.93333 1" />
      </material>
    </visual>
    <collision>
      <origin
        xyz="0 0 0"
        rpy="0 0 0" />
      <geometry>
        <mesh
          filename="package://shipbot_urdf/meshes/link1.STL" />
      </geometry>
    </collision>
  </link>
  <joint
    name="rotary1"
    type="continuous">
    <origin
      xyz="0 0 0"
      rpy="0 0 0" />
    <parent
      link="link0" />
    <child
      link="link1" />
    <axis
      xyz="0 0 1" />
    <limit
      lower="-1.57"
      upper="1.57"
      effort="7"
      velocity="2" />
  </joint>
  <transmission name="rotary1_trans">
    <type>transmission_interface/SimpleTransmission</type>
    <joint name="rotary1">
      <hardwareInterface>PositionJointInterface</hardwareInterface>
    </joint>
    <actuator name="rotary1_motor">
      <mechanicalReduction>1</mechanicalReduction>
    </actuator>
  </transmission>
  <link
    name="link2">
    <inertial>
      <origin
        xyz="0.2125 4.0162E-10 0.017645"
        rpy="0 0 0" />
      <mass
        value="0.10699" />
      <inertia
        ixx="2.5301E-05"
        ixy="-6.5998E-11"
        ixz="3.3983E-11"
        iyy="0.00085049"
        iyz="-6.1615E-13"
        izz="0.00085915" />
    </inertial>
    <visual>
      <origin
        xyz="0 0 0"
        rpy="0 0 0" />
      <geometry>
        <mesh
          filename="package://shipbot_urdf/meshes/link2.STL" />
      </geometry>
      <material
        name="">
        <color
          rgba="0.75294 0.75294 0.75294 1" />
      </material>
    </visual>
    <collision>
      <origin
        xyz="0 0 0"
        rpy="0 0 0" />
      <geometry>
        <mesh
          filename="package://shipbot_urdf/meshes/link2.STL" />
      </geometry>
    </collision>
  </link>
  <joint
    name="rotary2"
    type="continuous">
    <origin
      xyz="-0.06803 -0.00048045 0.070706"
      rpy="-1.5708 0 1.5708" />
    <parent
      link="link1" />
    <child
      link="link2" />
    <axis
      xyz="0 0 1" />
    <limit
      lower="-1.57"
      upper="1.57"
      effort="7"
      velocity="2.2" />
  </joint>
  <transmission name="rotary2_trans">
    <type>transmission_interface/SimpleTransmission</type>
    <joint name="rotary2">
      <hardwareInterface>PositionJointInterface</hardwareInterface>
    </joint>
    <actuator name="rotary2_motor">
      <mechanicalReduction>1</mechanicalReduction>
    </actuator>
  </transmission>
  <link
    name="link3">
    <inertial>
      <origin
        xyz="-0.17155 -0.0012809 -0.0063977"
        rpy="0 0 0" />
      <mass
        value="0.44203" />
      <inertia
        ixx="0.00014615"
        ixy="9.15E-06"
        ixz="-1.5422E-06"
        iyy="0.0010282"
        iyz="-1.4761E-07"
        izz="0.0011426" />
    </inertial>
    <visual>
      <origin
        xyz="0 0 0"
        rpy="0 0 0" />
      <geometry>
        <mesh
          filename="package://shipbot_urdf/meshes/link3.STL" />
      </geometry>
      <material
        name="">
        <color
          rgba="0.75294 0.75294 0.75294 1" />
      </material>
    </visual>
    <collision>
      <origin
        xyz="0 0 0"
        rpy="0 0 0" />
      <geometry>
        <mesh
          filename="package://shipbot_urdf/meshes/link3.STL" />
      </geometry>
    </collision>
  </link>
  <joint
    name="rotary3"
    type="continuous">
    <origin
      xyz="0.4064 0 -0.03105"
      rpy="3.1416 0 3.1416" />
    <parent
      link="link2" />
    <child
      link="link3" />
    <axis
      xyz="0 0 1" />
    <limit
      lower="-1.57"
      upper="1.57"
      effort="7"
      velocity="2.2" />
  </joint>
  <transmission name="rotary3_trans">
    <type>transmission_interface/SimpleTransmission</type>
    <joint name="rotary3">
      <hardwareInterface>PositionJointInterface</hardwareInterface>
    </joint>
    <actuator name="rotary3_motor">
      <mechanicalReduction>1</mechanicalReduction>
    </actuator>
  </transmission>
  <link
    name="link4">
    <inertial>
      <origin
        xyz="0.043568 0.0084987 0.049764"
        rpy="0 0 0" />
      <mass
        value="0.23698" />
      <inertia
        ixx="0.00018609"
        ixy="3.2809E-07"
        ixz="-4.3594E-07"
        iyy="8.7525E-05"
        iyz="-9.4885E-06"
        izz="0.00011907" />
    </inertial>
    <visual>
      <origin
        xyz="0 0 0"
        rpy="0 0 0" />
      <geometry>
        <mesh
          filename="package://shipbot_urdf/meshes/link4.STL" />
      </geometry>
      <material
        name="">
        <color
          rgba="0.79216 0.81961 0.93333 1" />
      </material>
    </visual>
    <collision>
      <origin
        xyz="0 0 0"
        rpy="0 0 0" />
      <geometry>
        <mesh
          filename="package://shipbot_urdf/meshes/link4.STL" />
      </geometry>
    </collision>
  </link>
  <joint
    name="rotary4"
    type="continuous">
    <origin
      xyz="-0.3302 0 -0.03"
      rpy="3.1416 0 3.1416" />
    <parent
      link="link3" />
    <child
      link="link4" />
    <axis
      xyz="0 0 1" />
    <limit
      lower="-1.57"
      upper="1.57"
      effort="7"
      velocity="2.2" />
  </joint>
  <transmission name="rotary4_trans">
    <type>transmission_interface/SimpleTransmission</type>
    <joint name="rotary4">
      <hardwareInterface>PositionJointInterface</hardwareInterface>
    </joint>
    <actuator name="rotary4_motor">
      <mechanicalReduction>1</mechanicalReduction>
    </actuator>
  </transmission>
  <link
    name="link5">
    <inertial>
      <origin
        xyz="-1.3878E-17 -5.5511E-17 0.023703"
        rpy="0 0 0" />
      <mass
        value="0.022265" />
      <inertia
        ixx="2.9665E-06"
        ixy="-5.8444E-23"
        ixz="-3.4064E-22"
        iyy="2.9665E-06"
        iyz="-5.2853E-21"
        izz="4.3029E-06" />
    </inertial>
    <visual>
      <origin
        xyz="0 0 0"
        rpy="0 0 0" />
      <geometry>
        <mesh
          filename="package://shipbot_urdf/meshes/link5.STL" />
      </geometry>
      <material
        name="">
        <color
          rgba="0.50196 0.50196 0.50196 1" />
      </material>
    </visual>
    <collision>
      <origin
        xyz="0 0 0"
        rpy="0 0 0" />
      <geometry>
        <mesh
          filename="package://shipbot_urdf/meshes/link5.STL" />
      </geometry>
    </collision>
  </link>
  <joint
    name="rotary5"
    type="continuous">
    <origin
      xyz="0.06855 0 0.05605"
      rpy="0 1.5708 0" />
    <parent
      link="link4" />
    <child
      link="link5" />
    <axis
      xyz="0 0 1" />
    <limit
      lower="-1.57"
      upper="1.57"
      effort="7"
      velocity="2.2" />
  </joint>
  <transmission name="rotary5_trans">
    <type>transmission_interface/SimpleTransmission</type>
    <joint name="rotary5">
      <hardwareInterface>PositionJointInterface</hardwareInterface>
    </joint>
    <actuator name="rotary5_motor">
      <mechanicalReduction>1</mechanicalReduction>
    </actuator>
  </transmission>
  <link name="end_effector" />
  <joint
    name="link5_to_end_effector"
    type="fixed">
    <origin
      xyz="0 0 0.044386" 
      rpy="0 0 0" />
    <parent
      link="link5" />
    <child
      link="end_effector"/>
  </joint>
</robot>
