<?xml version="1.0" encoding="utf-8"?>
<!-- This URDF was automatically created by SolidWorks to URDF Exporter! Originally created by Stephen Brawner (brawner@gmail.com) 
     Commit Version: 1.6.0-1-g15f4949  Build Version: 1.6.7594.29634
     For more information, please see http://wiki.ros.org/sw_urdf_exporter -->
<robot
  name="shipbot">
  <link
    name="link0">
    <inertial>
      <origin
        xyz="0.00229491428215301 0.00033379812623747 -0.0154857121766987"
        rpy="0 0 0" />
      <mass
        value="0.159501817678803" />
      <inertia
        ixx="8.44102418327143E-05"
        ixy="7.37059969004276E-08"
        ixz="4.57501855444665E-06"
        iyy="0.000133702392579779"
        iyz="-5.14045358890092E-08"
        izz="5.65734170944764E-05" />
    </inertial>
    <visual>
      <origin
        xyz="0 0 0"
        rpy="0 0 0" />
      <geometry>
        <mesh
          filename="package://shipbot_urdf/meshes/link0.STL" />
      </geometry>
      <material
        name="">
        <color
          rgba="0.792156862745098 0.819607843137255 0.933333333333333 1" />
      </material>
    </visual>
  </link>
  <link
    name="link1">
    <inertial>
      <origin
        xyz="0.00897913200851211 0.0644194045134585 0.0430481867787289"
        rpy="0 0 0" />
      <mass
        value="0.236983684615599" />
      <inertia
        ixx="8.75248409147893E-05"
        ixy="-9.48848077558243E-06"
        ixz="3.28088278467079E-07"
        iyy="0.000119070793291938"
        iyz="-4.35936038741718E-07"
        izz="0.000186089828377507" />
    </inertial>
    <visual>
      <origin
        xyz="0 0 0"
        rpy="0 0 0" />
      <geometry>
        <mesh
          filename="package://shipbot_urdf/meshes/link1.STL" />
      </geometry>
      <material
        name="">
        <color
          rgba="0.792156862745098 0.819607843137255 0.933333333333333 1" />
      </material>
    </visual>
  </link>
  <joint
    name="rotary1"
    type="revolute">
    <origin
      xyz="0 0 0"
      rpy="3.1416 1.5708 0" />
    <parent
      link="link0" />
    <child
      link="link1" />
    <axis
      xyz="0 0 1" />
    <limit
      lower="-1.57"
      upper="1.57"
      effort="7"
      velocity="2" />
  </joint>
  <link
    name="link2">
    <inertial>
      <origin
        xyz="0.212019577286543 -0.0707055312576384 0.0856748864948007"
        rpy="0 0 0" />
      <mass
        value="0.106988184234906" />
      <inertia
        ixx="2.53008670308476E-05"
        ixy="-6.59981024348689E-11"
        ixz="3.3983238247941E-11"
        iyy="0.00085049020237028"
        iyz="-6.16151850714375E-13"
        izz="0.000859153921810749" />
    </inertial>
    <visual>
      <origin
        xyz="0 0 0"
        rpy="0 0 0" />
      <geometry>
        <mesh
          filename="package://shipbot_urdf/meshes/link2.STL" />
      </geometry>
      <material
        name="">
        <color
          rgba="0.752941176470588 0.752941176470588 0.752941176470588 1" />
      </material>
    </visual>
  </link>
  <joint
    name="rotary2"
    type="revolute">
    <origin
      xyz="0 0 0"
      rpy="0 0 3.1416" />
    <parent
      link="link1" />
    <child
      link="link2" />
    <axis
      xyz="0 0 1" />
    <limit
      lower="-1.57"
      upper="1.57"
      effort="7"
      velocity="2.2" />
  </joint>
  <link
    name="link3">
    <inertial>
      <origin
        xyz="-0.596068862099029 -0.0719864106325815 -0.0433776786706706"
        rpy="0 0 0" />
      <mass
        value="0.442028154005472" />
      <inertia
        ixx="0.000146153858990964"
        ixy="9.14999965820475E-06"
        ixz="-1.54224631119548E-06"
        iyy="0.00102822733945739"
        iyz="-1.47610731127277E-07"
        izz="0.0011426345502513" />
    </inertial>
    <visual>
      <origin
        xyz="0 0 0"
        rpy="0 0 0" />
      <geometry>
        <mesh
          filename="package://shipbot_urdf/meshes/link3.STL" />
      </geometry>
      <material
        name="">
        <color
          rgba="0.752941176470588 0.752941176470588 0.752941176470588 1" />
      </material>
    </visual>
  </link>
  <joint
    name="rotary3"
    type="revolute">
    <origin
      xyz="0 0 0"
      rpy="3.1416 0 3.1416" />
    <parent
      link="link2" />
    <child
      link="link3" />
    <axis
      xyz="0 0 1" />
    <limit
      lower="-1.57"
      upper="1.57"
      effort="7"
      velocity="2.2" />
  </joint>
  <link
    name="link4">
    <inertial>
      <origin
        xyz="-0.0622068485470434 -0.116743813196765 -0.843087797291018"
        rpy="0 0 0" />
      <mass
        value="0.236983684646082" />
      <inertia
        ixx="8.75248406596663E-05"
        ixy="9.48848335855611E-06"
        ixz="-3.28088278854559E-07"
        iyy="0.000119070793706901"
        iyz="-4.35936053696684E-07"
        izz="0.000186089828536701" />
    </inertial>
    <visual>
      <origin
        xyz="0 0 0"
        rpy="0 0 0" />
      <geometry>
        <mesh
          filename="package://shipbot_urdf/meshes/link4.STL" />
      </geometry>
      <material
        name="">
        <color
          rgba="0.792156862745098 0.819607843137255 0.933333333333333 1" />
      </material>
    </visual>
  </link>
  <joint
    name="rotary4"
    type="revolute">
    <origin
      xyz="0 0 0"
      rpy="1.5708 0 1.5708" />
    <parent
      link="link3" />
    <child
      link="link4" />
    <axis
      xyz="0 0 1" />
    <limit
      lower="-1.57"
      upper="1.57"
      effort="7"
      velocity="2.2" />
  </joint>
  <link
    name="link5">
    <inertial>
      <origin
        xyz="-0.0182418735768112 0.140722679563569 0.891772257382688"
        rpy="0 0 0" />
      <mass
        value="0.0222650078147918" />
      <inertia
        ixx="2.96649808571935E-06"
        ixy="-7.41153828847513E-22"
        ixz="-1.05388523120848E-20"
        iyy="2.96649808571935E-06"
        iyz="9.69337532747787E-21"
        izz="4.30294027693138E-06" />
    </inertial>
    <visual>
      <origin
        xyz="0 0 0"
        rpy="0 0 0" />
      <geometry>
        <mesh
          filename="package://shipbot_urdf/meshes/link5.STL" />
      </geometry>
      <material
        name="">
        <color
          rgba="0.501960784313725 0.501960784313725 0.501960784313725 1" />
      </material>
    </visual>
  </link>
  <joint
    name="rotary5"
    type="revolute">
    <origin
      xyz="0 0 0"
      rpy="3.1416 0 -0.3927" />
    <parent
      link="link4" />
    <child
      link="link5" />
    <axis
      xyz="0 0 1" />
    <limit
      lower="-1.57"
      upper="1.57"
      effort="7"
      velocity="2.2" />
  </joint>
</robot>
